# 异常

![image-20240618155102430](C:\Users\30780\AppData\Roaming\Typora\typora-user-images\image-20240618155102430.png)

```c++
try
{
  // 保护的标识代码
}catch( ExceptionName e1 )
{
  // catch 块
}catch( ExceptionName e2 )
{
  // catch 块
}catch( ExceptionName eN )
{
  // catch 块
}

```

函数抛异常之后，该语句下之后的语句不会被执行，除了需要被销毁的已经创建的对象调用析构函数

![image-20240618161749701](C:\Users\30780\AppData\Roaming\Typora\typora-user-images\image-20240618161749701.png)

![image-20240618161423126](C:\Users\30780\AppData\Roaming\Typora\typora-user-images\image-20240618161423126.png)

```C++
// 服务器开发中通常使用的异常继承体系
class Exception
{
    public:
    Exception(const string& errmsg, int id)
        :_errmsg(errmsg)
            ,_id(id)
        {}
    virtual string what() const
    {
        return _errmsg;
    }
    protected:
    string _errmsg;
    int _id;
};
class SqlException : public Exception
{
    public:
    SqlException(const string& errmsg, int id, const string& sql)
        :Exception(errmsg, id)
            , _sql(sql)
        {}
    virtual string what() const
    {
        string str = "SqlException:";
        str += _errmsg;
        str += "->";
        str += _sql;
        return str;
    }
    private:
    const string _sql;
};
class CacheException : public Exception
{
    public:
    CacheException(const string& errmsg, int id)
        :Exception(errmsg, id)
        {}
    virtual string what() const
    {
        string str = "CacheException:";
        str += _errmsg;
        return str;
    }
};
class HttpServerException : public Exception
{
    public:
    HttpServerException(const string& errmsg, int id, const string& type)
        :Exception(errmsg, id)
            , _type(type)
        {}
    virtual string what() const
    {
        string str = "HttpServerException:";
        str += _type;
        str += ":";
        str += _errmsg;
        return str;
    }
    private:
    const string _type;
};
void SQLMgr()
{
    srand(time(0));
    if (rand() % 7 == 0)
    {
        throw SqlException("权限不足", 100, "select * from name = '张三'");
    }
    //throw "xxxxxx";
}
void CacheMgr()
{
    srand(time(0));
    if (rand() % 5 == 0)
    {
        throw CacheException("权限不足", 100);
    }
    else if (rand() % 6 == 0)
    {
        throw CacheException("数据不存在", 101);
    }
    SQLMgr();
}
void HttpServer()
{
    // ...
    srand(time(0));
    if (rand() % 3 == 0)
    {
        throw HttpServerException("请求资源不存在", 100, "get");
    }
    else if (rand() % 4 == 0)
    {
        throw HttpServerException("权限不足", 101, "post");
    }
    CacheMgr();
}
int main()
{
    while (1)
    {
        Sleep(500);
        try{
            HttpServer();
        }
        catch (const Exception& e) // 这里捕获父类对象就可以
        {
            // 多态
            cout << e.what() << endl;
        }
        catch (...)
        {
            cout << "Unkown Exception" << endl;
        }
    }
    return 0;
}

```

**每一部分异常都继承于基类的异常规范，捕获时使用多态获得异常信息**

##  C++异常库

![image-20240618165608054](C:\Users\30780\AppData\Roaming\Typora\typora-user-images\image-20240618165608054.png)

## 异常的重新抛出

防止在异常之前分配的空间，因为异常跳出导致内存没有被释放

```C++
void Func()
{
	// 这里可以看到如果发生除0错误抛出异常，另外下面的array没有得到释放。
	// 所以这里捕获异常后并不处理异常，异常还是交给外面处理，这里捕获了再
	// 重新抛出去。
	int* array = new int[10];
	// 异常安全问题
	try {
		int len, time;
		cin >> len >> time;
		cout << Division(len, time) << endl;
	}
	catch (const char* errmsg)
	{
		cout << "delete []" << array << endl;
		delete[] array;

		throw errmsg;
	}

	cout << "delete []" << array << endl;
	delete[] array;

}
```

同时也可以使用   ...  接收一切异常情况在catch中把资源释放

```c++
int* array1 = new int[10];
int* array2 = new int[20];

// 异常安全问题
try {
	int len, time;
	cin >> len >> time;
	cout << Division(len, time) << endl;
}
catch (...)
{
	cout << "delete []" << array1 << endl;
	delete[] array1;

	cout << "delete []" << array2 << endl;
	delete[] array2;

	throw;  // 捕到什么抛什么
}
```

但是，如果array2出现异常问题，就需要对array1进行资源释放重新抛出，依次类推，导致很冗余，这里需要智能指针解决问题

**这些问题的源头时因为 异常的执行是跳跃的**

## 异常安全

![image-20240618171253188](C:\Users\30780\AppData\Roaming\Typora\typora-user-images\image-20240618171253188.png)

## 异常规范

![image-20240618171321847](C:\Users\30780\AppData\Roaming\Typora\typora-user-images\image-20240618171321847.png)

```c++
double Division(int a, int b) throw(const char*)
{
	// 当b == 0时抛出异常
	if (b == 0)
	{
		throw "Division by zero condition!";
	}
	return (double)a / (double)b;
}
```

这个规范，只是一个规范，怎么写编译器不做强制检查，但是，写上还是代码可读性高些

**C++ 11 中 noexcept  就不会捕获异常即使有异常** 

**C++98 throw（）应然会抛异常**

## 优缺点



![](C:\Users\30780\AppData\Roaming\Typora\typora-user-images\image-20240618173124882.png)

![image-20240618173133844](C:\Users\30780\AppData\Roaming\Typora\typora-user-images\image-20240618173133844.png)